Workbook

Sheet Constants
A1: Physicochemical constants feeding |U_sec| and Kramers escape
A2: BLUE = hardcoded input, edit here and every derived cell in this workbook follows. Black = formula. Sources named in the last column.
A4: symbol | B4: quantity | C4: value | D4: unit | E4: source / note
A5: e | B5: elementary charge | C5: 1.602e-19 | D5: C | E5: CODATA; as used in fx_vs_usec.py
A6: k_B | B6: Boltzmann constant | C6: 1.381e-23 | D6: J/K | E6: CODATA; as used in fx_vs_usec.py
A7: T | B7: absolute temperature | C7: 293.2 | D7: K | E7: 293.2 K = 20.05 C. Fixed in fx_vs_usec.py / dlvo_kramers_size.py
A8: eps_0 | B8: vacuum permittivity | C8: 8.854e-12 | D8: F/m | E8: CODATA
A9: eps_r | B9: relative permittivity of water | C9: 80 | D9: - | E9: 80.0 at 20 C, as used throughout
A10: N_A | B10: Avogadro constant | C10: 6.022e+23 | D10: 1/mol | E10: CODATA
A11: z | B11: counter-ion valence | C11: 1 | D11: - | E11: 1 -- all Li/Tong electrolytes are 1:1 (NaCl)
A12: lambda | B12: vdW retardation wavelength | C12: 1e-07 | D12: m | E12: 100 nm; Gregory retardation, matched to Johnson 2018
A13: mu | B13: dynamic viscosity of water | C13: 0.001 | D13: Pa s | E13: 1.0e-3; Kramers prefactor only (dlvo_kramers_size.py)
A14: h_min | B14: lower bound of the |U_sec| search | C14: 8e-09 | D14: m | E14: 8 nm. Below this the primary minimum dominates and the search would find it instead
A15: h_grid | B15: energy-profile grid | C15: 70000 | D15: points | E15: linspace(2e-9, 140e-9, 70000) m -- IDENTICAL to fx_vs_usec.usec(); h_sec is grid-resolved to ~2 pm
A17: kT | B17: thermal energy | C17: =C6*C7 -> 4.049092e-21 | D17: J | E17: k_B * T -- the energy unit every |U_sec| in this workbook is divided by.
A19: Kramers anchor | B19: glass shared k_r | C19: 5.58e-05 | D19: /s at 1.1 um | E19: serial3_size_fit.py joint fit. Used ONLY to anchor the Kramers curve so its SIZE SLOPE can be compared with the fitted k_r; the absolute Kramers rate is ~1e8x higher. NOTE this is the SUPERSEDED constant (current: glass 3.75e-5 /s) -- kept because the published anchored curve used it.

Sheet Zeta_Hamaker
A1: Zeta potentials and Hamaker constants -- Johnson 2018 Table SI-1
A2: BLUE = measured input. GREY = NO MEASUREMENT EXISTS. Do not fill a grey cell with an invented or silently interpolated value; any column at that ionic strength simply carries no |U_sec|.
A4: ionic strength (mM) | B4: zeta colloid (V) | C4: zeta collector, glass (V) | D4: zeta collector, quartz (V) | E4: note
A5: 1 | B5: no measurement | C5: no measurement | D5: no measurement | E5: Table SI-1 covers 6 / 20 / 50 mM only -- NO colloid zeta at this IS
A6: 3 | B6: no measurement | C6: no measurement | D6: no measurement | E6: Table SI-1 covers 6 / 20 / 50 mM only -- NO colloid zeta at this IS. 3 mM IS IN THE MANUSCRIPT: this gap must be closed with a measured or explicitly-flagged interpolated value
A7: 6 | B7: -0.064 | C7: -0.07 | D7: -0.083
A8: 10 | B8: no measurement | C8: no measurement | D8: no measurement | E8: Table SI-1 covers 6 / 20 / 50 mM only -- NO colloid zeta at this IS
A9: 20 | B9: -0.05 | C9: -0.051 | D9: -0.069
A10: 50 | B10: -0.04 | C10: -0.038 | D10: no measurement | E10: quartz COLLECTOR not measured at 50 mM (Table SI-1 gives quartz at 6 / 20 mM)
A13: Hamaker constant A132 (colloid-water-collector)
A14: medium | B14: A132 (J) | C14: source
A15: glass | B15: 7.17e-21 | C15: polystyrene-water-glass
A16: quartz | B16: 1.96e-20 | C16: polystyrene-water-quartz

Sheet Usec_grid
A1: |U_sec| for every colloid size x ionic strength x medium
A2: |U_sec|/kT = -min over h>8nm of [ U_vdw(h) + U_edl(h) ] / kT, sphere-plate (grain >> colloid). Every column here is a FORMULA except h_sec, which needs a numerical minimisation over a 70,000-point grid and is written as a value (blue). The energies are then evaluated AT that h. Change a zeta materially and h_sec should be re-derived by re-running dlvo_parameter_table.py.
A3: Rows with no zeta at that ionic strength are greyed and carry no energies. 'in Li/Tong set?' marks the combinations that are actual experiments; the rest are filled in so the parameter space can be inspected for a-priori work.
A5: medium | B5: diameter (um) | C5: a_p radius (m) | D5: IS (mM) | E5: I (mol/m3) | F5: A132 (J) | G5: zeta colloid (V) | H5: zeta collector (V) | I5: kappa (1/m) | J5: Debye length (nm) | K5: G1 = tanh(ze*z1/4kT) | L5: G2 = tanh(ze*z2/4kT) | M5: h_sec (nm) | N5: U_vdw(h_sec)/kT | O5: U_edl(h_sec)/kT | P5: |U_sec| (kT) | Q5: in Li/Tong set?
A6: glass | B6: 0.1 | C6: =B6/2*0.000001 -> 5e-08 | D6: 1 | E6: =D6 -> 1 | F6: =Zeta_Hamaker!$B$15 -> 7.17e-21 | G6: no zeta | H6: no zeta | Q6: -
A7: glass | B7: 0.1 | C7: =B7/2*0.000001 -> 5e-08 | D7: 3 | E7: =D7 -> 3 | F7: =Zeta_Hamaker!$B$15 -> 7.17e-21 | G7: no zeta | H7: no zeta | Q7: -
A8: glass | B8: 0.1 | C8: =B8/2*0.000001 -> 5e-08 | D8: 6 | E8: =D8 -> 6 | F8: =Zeta_Hamaker!$B$15 -> 7.17e-21 | G8: =Zeta_Hamaker!$B$7 -> -0.064 | H8: =Zeta_Hamaker!$C$7 -> -0.07 | I8: =SQRT(2*Constants!$C$10*Constants!$C$5^2*E8/(Constants!$C$8*Constants!$C$9*Constants!$C$17)) -> 2.5429038e+08 | J8: =1/I8*1000000000 -> 3.9325121 | K8: =TANH(Constants!$C$11*Constants!$C$5*G8/(4*Constants!$C$17)) -> -0.56013564 | L8: =TANH(Constants!$C$11*Constants!$C$5*H8/(4*Constants!$C$17)) -> -0.59950715 | M8: 41.88257 | N8: =(-(F8*C8/(6*M8/1000000000))/(1+14*(M8/1000000000)/Constants!$C$12))/Constants!$C$17 -> -0.051333104 | O8: =64*PI()*Constants!$C$8*Constants!$C$9*C8*(Constants!$C$17/(Constants!$C$11*Constants!$C$5))^2*K8*L8*EXP(-I8*(M8/1000000000))/Constants!$C$17 -> 0.0089385681 | P8: =MAX(-(N8+O8),0) -> 0.042394536 | Q8: -
A9: glass | B9: 0.1 | C9: =B9/2*0.000001 -> 5e-08 | D9: 10 | E9: =D9 -> 10 | F9: =Zeta_Hamaker!$B$15 -> 7.17e-21 | G9: no zeta | H9: no zeta | Q9: -
A10: glass | B10: 0.1 | C10: =B10/2*0.000001 -> 5e-08 | D10: 20 | E10: =D10 -> 20 | F10: =Zeta_Hamaker!$B$15 -> 7.17e-21 | G10: =Zeta_Hamaker!$B$9 -> -0.05 | H10: =Zeta_Hamaker!$C$9 -> -0.051 | I10: =SQRT(2*Constants!$C$10*Constants!$C$5^2*E10/(Constants!$C$8*Constants!$C$9*Constants!$C$17)) -> 4.642686e+08 | J10: =1/I10*1000000000 -> 2.1539256 | K10: =TANH(Constants!$C$11*Constants!$C$5*G10/(4*Constants!$C$17)) -> -0.45782444 | L10: =TANH(Constants!$C$11*Constants!$C$5*H10/(4*Constants!$C$17)) -> -0.46560685 | M10: 18.503064 | N10: =(-(F10*C10/(6*M10/1000000000))/(1+14*(M10/1000000000)/Constants!$C$12))/Constants!$C$17 -> -0.22212133 | O10: =64*PI()*Constants!$C$8*Constants!$C$9*C10*(Constants!$C$17/(Constants!$C$11*Constants!$C$5))^2*K10*L10*EXP(-I10*(M10/1000000000))/Constants!$C$17 -> 0.044516458 | P10: =MAX(-(N10+O10),0) -> 0.17760487 | Q10: yes
A11: glass | B11: 0.1 | C11: =B11/2*0.000001 -> 5e-08 | D11: 50 | E11: =D11 -> 50 | F11: =Zeta_Hamaker!$B$15 -> 7.17e-21 | G11: =Zeta_Hamaker!$B$10 -> -0.04 | H11: =Zeta_Hamaker!$C$10 -> -0.038 | I11: =SQRT(2*Constants!$C$10*Constants!$C$5^2*E11/(Constants!$C$8*Constants!$C$9*Constants!$C$17)) -> 7.3407311e+08 | J11: =1/I11*1000000000 -> 1.3622621 | K11: =TANH(Constants!$C$11*Constants!$C$5*G11/(4*Constants!$C$17)) -> -0.37621587 | L11: =TANH(Constants!$C$11*Constants!$C$5*H11/(4*Constants!$C$17)) -> -0.35910851 | M11: 9.3850769 | N11: =(-(F11*C11/(6*M11/1000000000))/(1+14*(M11/1000000000)/Constants!$C$12))/Constants!$C$17 -> -0.67950995 | O11: =64*PI()*Constants!$C$8*Constants!$C$9*C11*(Constants!$C$17/(Constants!$C$11*Constants!$C$5))^2*K11*L11*EXP(-I11*(M11/1000000000))/Constants!$C$17 -> 0.15460576 | P11: =MAX(-(N11+O11),0) -> 0.52490419 | Q11: yes
A12: glass | B12: 0.2 | C12: =B12/2*0.000001 -> 1e-07 | D12: 1 | E12: =D12 -> 1 | F12: =Zeta_Hamaker!$B$15 -> 7.17e-21 | G12: no zeta | H12: no zeta | Q12: -
A13: glass | B13: 0.2 | C13: =B13/2*0.000001 -> 1e-07 | D13: 3 | E13: =D13 -> 3 | F13: =Zeta_Hamaker!$B$15 -> 7.17e-21 | G13: no zeta | H13: no zeta | Q13: -
A14: glass | B14: 0.2 | C14: =B14/2*0.000001 -> 1e-07 | D14: 6 | E14: =D14 -> 6 | F14: =Zeta_Hamaker!$B$15 -> 7.17e-21 | G14: =Zeta_Hamaker!$B$7 -> -0.064 | H14: =Zeta_Hamaker!$C$7 -> -0.07 | I14: =SQRT(2*Constants!$C$10*Constants!$C$5^2*E14/(Constants!$C$8*Constants!$C$9*Constants!$C$17)) -> 2.5429038e+08 | J14: =1/I14*1000000000 -> 3.9325121 | K14: =TANH(Constants!$C$11*Constants!$C$5*G14/(4*Constants!$C$17)) -> -0.56013564 | L14: =TANH(Constants!$C$11*Constants!$C$5*H14/(4*Constants!$C$17)) -> -0.59950715 | M14: 41.88257 | N14: =(-(F14*C14/(6*M14/1000000000))/(1+14*(M14/1000000000)/Constants!$C$12))/Constants!$C$17 -> -0.10266621 | O14: =64*PI()*Constants!$C$8*Constants!$C$9*C14*(Constants!$C$17/(Constants!$C$11*Constants!$C$5))^2*K14*L14*EXP(-I14*(M14/1000000000))/Constants!$C$17 -> 0.017877136 | P14: =MAX(-(N14+O14),0) -> 0.084789072 | Q14: -
A15: glass | B15: 0.2 | C15: =B15/2*0.000001 -> 1e-07 | D15: 10 | E15: =D15 -> 10 | F15: =Zeta_Hamaker!$B$15 -> 7.17e-21 | G15: no zeta | H15: no zeta | Q15: -
A16: glass | B16: 0.2 | C16: =B16/2*0.000001 -> 1e-07 | D16: 20 | E16: =D16 -> 20 | F16: =Zeta_Hamaker!$B$15 -> 7.17e-21 | G16: =Zeta_Hamaker!$B$9 -> -0.05 | H16: =Zeta_Hamaker!$C$9 -> -0.051 | I16: =SQRT(2*Constants!$C$10*Constants!$C$5^2*E16/(Constants!$C$8*Constants!$C$9*Constants!$C$17)) -> 4.642686e+08 | J16: =1/I16*1000000000 -> 2.1539256 | K16: =TANH(Constants!$C$11*Constants!$C$5*G16/(4*Constants!$C$17)) -> -0.45782444 | L16: =TANH(Constants!$C$11*Constants!$C$5*H16/(4*Constants!$C$17)) -> -0.46560685 | M16: 18.503064 | N16: =(-(F16*C16/(6*M16/1000000000))/(1+14*(M16/1000000000)/Constants!$C$12))/Constants!$C$17 -> -0.44424266 | O16: =64*PI()*Constants!$C$8*Constants!$C$9*C16*(Constants!$C$17/(Constants!$C$11*Constants!$C$5))^2*K16*L16*EXP(-I16*(M16/1000000000))/Constants!$C$17 -> 0.089032915 | P16: =MAX(-(N16+O16),0) -> 0.35520974 | Q16: yes
A17: glass | B17: 0.2 | C17: =B17/2*0.000001 -> 1e-07 | D17: 50 | E17: =D17 -> 50 | F17: =Zeta_Hamaker!$B$15 -> 7.17e-21 | G17: =Zeta_Hamaker!$B$10 -> -0.04 | H17: =Zeta_Hamaker!$C$10 -> -0.038 | I17: =SQRT(2*Constants!$C$10*Constants!$C$5^2*E17/(Constants!$C$8*Constants!$C$9*Constants!$C$17)) -> 7.3407311e+08 | J17: =1/I17*1000000000 -> 1.3622621 | K17: =TANH(Constants!$C$11*Constants!$C$5*G17/(4*Constants!$C$17)) -> -0.37621587 | L17: =TANH(Constants!$C$11*Constants!$C$5*H17/(4*Constants!$C$17)) -> -0.35910851 | M17: 9.3850769 | N17: =(-(F17*C17/(6*M17/1000000000))/(1+14*(M17/1000000000)/Constants!$C$12))/Constants!$C$17 -> -1.3590199 | O17: =64*PI()*Constants!$C$8*Constants!$C$9*C17*(Constants!$C$17/(Constants!$C$11*Constants!$C$5))^2*K17*L17*EXP(-I17*(M17/1000000000))/Constants!$C$17 -> 0.30921151 | P17: =MAX(-(N17+O17),0) -> 1.0498084 | Q17: yes
A18: glass | B18: 0.5 | C18: =B18/2*0.000001 -> 2.5e-07 | D18: 1 | E18: =D18 -> 1 | F18: =Zeta_Hamaker!$B$15 -> 7.17e-21 | G18: no zeta | H18: no zeta | Q18: -
A19: glass | B19: 0.5 | C19: =B19/2*0.000001 -> 2.5e-07 | D19: 3 | E19: =D19 -> 3 | F19: =Zeta_Hamaker!$B$15 -> 7.17e-21 | G19: no zeta | H19: no zeta | Q19: -
A20: glass | B20: 0.5 | C20: =B20/2*0.000001 -> 2.5e-07 | D20: 6 | E20: =D20 -> 6 | F20: =Zeta_Hamaker!$B$15 -> 7.17e-21 | G20: =Zeta_Hamaker!$B$7 -> -0.064 | H20: =Zeta_Hamaker!$C$7 -> -0.07 | I20: =SQRT(2*Constants!$C$10*Constants!$C$5^2*E20/(Constants!$C$8*Constants!$C$9*Constants!$C$17)) -> 2.5429038e+08 | J20: =1/I20*1000000000 -> 3.9325121 | K20: =TANH(Constants!$C$11*Constants!$C$5*G20/(4*Constants!$C$17)) -> -0.56013564 | L20: =TANH(Constants!$C$11*Constants!$C$5*H20/(4*Constants!$C$17)) -> -0.59950715 | M20: 41.88257 | N20: =(-(F20*C20/(6*M20/1000000000))/(1+14*(M20/1000000000)/Constants!$C$12))/Constants!$C$17 -> -0.25666552 | O20: =64*PI()*Constants!$C$8*Constants!$C$9*C20*(Constants!$C$17/(Constants!$C$11*Constants!$C$5))^2*K20*L20*EXP(-I20*(M20/1000000000))/Constants!$C$17 -> 0.044692841 | P20: =MAX(-(N20+O20),0) -> 0.21197268 | Q20: -
A21: glass | B21: 0.5 | C21: =B21/2*0.000001 -> 2.5e-07 | D21: 10 | E21: =D21 -> 10 | F21: =Zeta_Hamaker!$B$15 -> 7.17e-21 | G21: no zeta | H21: no zeta | Q21: -
A22: glass | B22: 0.5 | C22: =B22/2*0.000001 -> 2.5e-07 | D22: 20 | E22: =D22 -> 20 | F22: =Zeta_Hamaker!$B$15 -> 7.17e-21 | G22: =Zeta_Hamaker!$B$9 -> -0.05 | H22: =Zeta_Hamaker!$C$9 -> -0.051 | I22: =SQRT(2*Constants!$C$10*Constants!$C$5^2*E22/(Constants!$C$8*Constants!$C$9*Constants!$C$17)) -> 4.642686e+08 | J22: =1/I22*1000000000 -> 2.1539256 | K22: =TANH(Constants!$C$11*Constants!$C$5*G22/(4*Constants!$C$17)) -> -0.45782444 | L22: =TANH(Constants!$C$11*Constants!$C$5*H22/(4*Constants!$C$17)) -> -0.46560685 | M22: 18.503064 | N22: =(-(F22*C22/(6*M22/1000000000))/(1+14*(M22/1000000000)/Constants!$C$12))/Constants!$C$17 -> -1.1106066 | O22: =64*PI()*Constants!$C$8*Constants!$C$9*C22*(Constants!$C$17/(Constants!$C$11*Constants!$C$5))^2*K22*L22*EXP(-I22*(M22/1000000000))/Constants!$C$17 -> 0.22258229 | P22: =MAX(-(N22+O22),0) -> 0.88802435 | Q22: yes
A23: glass | B23: 0.5 | C23: =B23/2*0.000001 -> 2.5e-07 | D23: 50 | E23: =D23 -> 50 | F23: =Zeta_Hamaker!$B$15 -> 7.17e-21 | G23: =Zeta_Hamaker!$B$10 -> -0.04 | H23: =Zeta_Hamaker!$C$10 -> -0.038 | I23: =SQRT(2*Constants!$C$10*Constants!$C$5^2*E23/(Constants!$C$8*Constants!$C$9*Constants!$C$17)) -> 7.3407311e+08 | J23: =1/I23*1000000000 -> 1.3622621 | K23: =TANH(Constants!$C$11*Constants!$C$5*G23/(4*Constants!$C$17)) -> -0.37621587 | L23: =TANH(Constants!$C$11*Constants!$C$5*H23/(4*Constants!$C$17)) -> -0.35910851 | M23: 9.3850769 | N23: =(-(F23*C23/(6*M23/1000000000))/(1+14*(M23/1000000000)/Constants!$C$12))/Constants!$C$17 -> -3.3975498 | O23: =64*PI()*Constants!$C$8*Constants!$C$9*C23*(Constants!$C$17/(Constants!$C$11*Constants!$C$5))^2*K23*L23*EXP(-I23*(M23/1000000000))/Constants!$C$17 -> 0.77302878 | P23: =MAX(-(N23+O23),0) -> 2.624521 | Q23: yes
A24: glass | B24: 0.98 | C24: =B24/2*0.000001 -> 4.9e-07 | D24: 1 | E24: =D24 -> 1 | F24: =Zeta_Hamaker!$B$15 -> 7.17e-21 | G24: no zeta | H24: no zeta | Q24: -
A25: glass | B25: 0.98 | C25: =B25/2*0.000001 -> 4.9e-07 | D25: 3 | E25: =D25 -> 3 | F25: =Zeta_Hamaker!$B$15 -> 7.17e-21 | G25: no zeta | H25: no zeta | Q25: -
A26: glass | B26: 0.98 | C26: =B26/2*0.000001 -> 4.9e-07 | D26: 6 | E26: =D26 -> 6 | F26: =Zeta_Hamaker!$B$15 -> 7.17e-21 | G26: =Zeta_Hamaker!$B$7 -> -0.064 | H26: =Zeta_Hamaker!$C$7 -> -0.07 | I26: =SQRT(2*Constants!$C$10*Constants!$C$5^2*E26/(Constants!$C$8*Constants!$C$9*Constants!$C$17)) -> 2.5429038e+08 | J26: =1/I26*1000000000 -> 3.9325121 | K26: =TANH(Constants!$C$11*Constants!$C$5*G26/(4*Constants!$C$17)) -> -0.56013564 | L26: =TANH(Constants!$C$11*Constants!$C$5*H26/(4*Constants!$C$17)) -> -0.59950715 | M26: 41.88257 | N26: =(-(F26*C26/(6*M26/1000000000))/(1+14*(M26/1000000000)/Constants!$C$12))/Constants!$C$17 -> -0.50306442 | O26: =64*PI()*Constants!$C$8*Constants!$C$9*C26*(Constants!$C$17/(Constants!$C$11*Constants!$C$5))^2*K26*L26*EXP(-I26*(M26/1000000000))/Constants!$C$17 -> 0.087597967 | P26: =MAX(-(N26+O26),0) -> 0.41546645 | Q26: -
A27: glass | B27: 0.98 | C27: =B27/2*0.000001 -> 4.9e-07 | D27: 10 | E27: =D27 -> 10 | F27: =Zeta_Hamaker!$B$15 -> 7.17e-21 | G27: no zeta | H27: no zeta | Q27: yes
A28: glass | B28: 0.98 | C28: =B28/2*0.000001 -> 4.9e-07 | D28: 20 | E28: =D28 -> 20 | F28: =Zeta_Hamaker!$B$15 -> 7.17e-21 | G28: =Zeta_Hamaker!$B$9 -> -0.05 | H28: =Zeta_Hamaker!$C$9 -> -0.051 | I28: =SQRT(2*Constants!$C$10*Constants!$C$5^2*E28/(Constants!$C$8*Constants!$C$9*Constants!$C$17)) -> 4.642686e+08 | J28: =1/I28*1000000000 -> 2.1539256 | K28: =TANH(Constants!$C$11*Constants!$C$5*G28/(4*Constants!$C$17)) -> -0.45782444 | L28: =TANH(Constants!$C$11*Constants!$C$5*H28/(4*Constants!$C$17)) -> -0.46560685 | M28: 18.503064 | N28: =(-(F28*C28/(6*M28/1000000000))/(1+14*(M28/1000000000)/Constants!$C$12))/Constants!$C$17 -> -2.176789 | O28: =64*PI()*Constants!$C$8*Constants!$C$9*C28*(Constants!$C$17/(Constants!$C$11*Constants!$C$5))^2*K28*L28*EXP(-I28*(M28/1000000000))/Constants!$C$17 -> 0.43626129 | P28: =MAX(-(N28+O28),0) -> 1.7405277 | Q28: -
A29: glass | B29: 0.98 | C29: =B29/2*0.000001 -> 4.9e-07 | D29: 50 | E29: =D29 -> 50 | F29: =Zeta_Hamaker!$B$15 -> 7.17e-21 | G29: =Zeta_Hamaker!$B$10 -> -0.04 | H29: =Zeta_Hamaker!$C$10 -> -0.038 | I29: =SQRT(2*Constants!$C$10*Constants!$C$5^2*E29/(Constants!$C$8*Constants!$C$9*Constants!$C$17)) -> 7.3407311e+08 | J29: =1/I29*1000000000 -> 1.3622621 | K29: =TANH(Constants!$C$11*Constants!$C$5*G29/(4*Constants!$C$17)) -> -0.37621587 | L29: =TANH(Constants!$C$11*Constants!$C$5*H29/(4*Constants!$C$17)) -> -0.35910851 | M29: 9.3850769 | N29: =(-(F29*C29/(6*M29/1000000000))/(1+14*(M29/1000000000)/Constants!$C$12))/Constants!$C$17 -> -6.6591975 | O29: =64*PI()*Constants!$C$8*Constants!$C$9*C29*(Constants!$C$17/(Constants!$C$11*Constants!$C$5))^2*K29*L29*EXP(-I29*(M29/1000000000))/Constants!$C$17 -> 1.5151364 | P29: =MAX(-(N29+O29),0) -> 5.1440611 | Q29: -
A30: glass | B30: 1 | C30: =B30/2*0.000001 -> 5e-07 | D30: 1 | E30: =D30 -> 1 | F30: =Zeta_Hamaker!$B$15 -> 7.17e-21 | G30: no zeta | H30: no zeta | Q30: -
A31: glass | B31: 1 | C31: =B31/2*0.000001 -> 5e-07 | D31: 3 | E31: =D31 -> 3 | F31: =Zeta_Hamaker!$B$15 -> 7.17e-21 | G31: no zeta | H31: no zeta | Q31: -
A32: glass | B32: 1 | C32: =B32/2*0.000001 -> 5e-07 | D32: 6 | E32: =D32 -> 6 | F32: =Zeta_Hamaker!$B$15 -> 7.17e-21 | G32: =Zeta_Hamaker!$B$7 -> -0.064 | H32: =Zeta_Hamaker!$C$7 -> -0.07 | I32: =SQRT(2*Constants!$C$10*Constants!$C$5^2*E32/(Constants!$C$8*Constants!$C$9*Constants!$C$17)) -> 2.5429038e+08 | J32: =1/I32*1000000000 -> 3.9325121 | K32: =TANH(Constants!$C$11*Constants!$C$5*G32/(4*Constants!$C$17)) -> -0.56013564 | L32: =TANH(Constants!$C$11*Constants!$C$5*H32/(4*Constants!$C$17)) -> -0.59950715 | M32: 41.88257 | N32: =(-(F32*C32/(6*M32/1000000000))/(1+14*(M32/1000000000)/Constants!$C$12))/Constants!$C$17 -> -0.51333104 | O32: =64*PI()*Constants!$C$8*Constants!$C$9*C32*(Constants!$C$17/(Constants!$C$11*Constants!$C$5))^2*K32*L32*EXP(-I32*(M32/1000000000))/Constants!$C$17 -> 0.089385681 | P32: =MAX(-(N32+O32),0) -> 0.42394536 | Q32: -
A33: glass | B33: 1 | C33: =B33/2*0.000001 -> 5e-07 | D33: 10 | E33: =D33 -> 10 | F33: =Zeta_Hamaker!$B$15 -> 7.17e-21 | G33: no zeta | H33: no zeta | Q33: -
A34: glass | B34: 1 | C34: =B34/2*0.000001 -> 5e-07 | D34: 20 | E34: =D34 -> 20 | F34: =Zeta_Hamaker!$B$15 -> 7.17e-21 | G34: =Zeta_Hamaker!$B$9 -> -0.05 | H34: =Zeta_Hamaker!$C$9 -> -0.051 | I34: =SQRT(2*Constants!$C$10*Constants!$C$5^2*E34/(Constants!$C$8*Constants!$C$9*Constants!$C$17)) -> 4.642686e+08 | J34: =1/I34*1000000000 -> 2.1539256 | K34: =TANH(Constants!$C$11*Constants!$C$5*G34/(4*Constants!$C$17)) -> -0.45782444 | L34: =TANH(Constants!$C$11*Constants!$C$5*H34/(4*Constants!$C$17)) -> -0.46560685 | M34: 18.503064 | N34: =(-(F34*C34/(6*M34/1000000000))/(1+14*(M34/1000000000)/Constants!$C$12))/Constants!$C$17 -> -2.2212133 | O34: =64*PI()*Constants!$C$8*Constants!$C$9*C34*(Constants!$C$17/(Constants!$C$11*Constants!$C$5))^2*K34*L34*EXP(-I34*(M34/1000000000))/Constants!$C$17 -> 0.44516458 | P34: =MAX(-(N34+O34),0) -> 1.7760487 | Q34: yes
A35: glass | B35: 1 | C35: =B35/2*0.000001 -> 5e-07 | D35: 50 | E35: =D35 -> 50 | F35: =Zeta_Hamaker!$B$15 -> 7.17e-21 | G35: =Zeta_Hamaker!$B$10 -> -0.04 | H35: =Zeta_Hamaker!$C$10 -> -0.038 | I35: =SQRT(2*Constants!$C$10*Constants!$C$5^2*E35/(Constants!$C$8*Constants!$C$9*Constants!$C$17)) -> 7.3407311e+08 | J35: =1/I35*1000000000 -> 1.3622621 | K35: =TANH(Constants!$C$11*Constants!$C$5*G35/(4*Constants!$C$17)) -> -0.37621587 | L35: =TANH(Constants!$C$11*Constants!$C$5*H35/(4*Constants!$C$17)) -> -0.35910851 | M35: 9.3850769 | N35: =(-(F35*C35/(6*M35/1000000000))/(1+14*(M35/1000000000)/Constants!$C$12))/Constants!$C$17 -> -6.7950995 | O35: =64*PI()*Constants!$C$8*Constants!$C$9*C35*(Constants!$C$17/(Constants!$C$11*Constants!$C$5))^2*K35*L35*EXP(-I35*(M35/1000000000))/Constants!$C$17 -> 1.5460576 | P35: =MAX(-(N35+O35),0) -> 5.2490419 | Q35: yes
A36: glass | B36: 1.1 | C36: =B36/2*0.000001 -> 5.5e-07 | D36: 1 | E36: =D36 -> 1 | F36: =Zeta_Hamaker!$B$15 -> 7.17e-21 | G36: no zeta | H36: no zeta | Q36: -
A37: glass | B37: 1.1 | C37: =B37/2*0.000001 -> 5.5e-07 | D37: 3 | E37: =D37 -> 3 | F37: =Zeta_Hamaker!$B$15 -> 7.17e-21 | G37: no zeta | H37: no zeta | Q37: -
A38: glass | B38: 1.1 | C38: =B38/2*0.000001 -> 5.5e-07 | D38: 6 | E38: =D38 -> 6 | F38: =Zeta_Hamaker!$B$15 -> 7.17e-21 | G38: =Zeta_Hamaker!$B$7 -> -0.064 | H38: =Zeta_Hamaker!$C$7 -> -0.07 | I38: =SQRT(2*Constants!$C$10*Constants!$C$5^2*E38/(Constants!$C$8*Constants!$C$9*Constants!$C$17)) -> 2.5429038e+08 | J38: =1/I38*1000000000 -> 3.9325121 | K38: =TANH(Constants!$C$11*Constants!$C$5*G38/(4*Constants!$C$17)) -> -0.56013564 | L38: =TANH(Constants!$C$11*Constants!$C$5*H38/(4*Constants!$C$17)) -> -0.59950715 | M38: 41.88257 | N38: =(-(F38*C38/(6*M38/1000000000))/(1+14*(M38/1000000000)/Constants!$C$12))/Constants!$C$17 -> -0.56466414 | O38: =64*PI()*Constants!$C$8*Constants!$C$9*C38*(Constants!$C$17/(Constants!$C$11*Constants!$C$5))^2*K38*L38*EXP(-I38*(M38/1000000000))/Constants!$C$17 -> 0.098324249 | P38: =MAX(-(N38+O38),0) -> 0.46633989 | Q38: yes
A39: glass | B39: 1.1 | C39: =B39/2*0.000001 -> 5.5e-07 | D39: 10 | E39: =D39 -> 10 | F39: =Zeta_Hamaker!$B$15 -> 7.17e-21 | G39: no zeta | H39: no zeta | Q39: -
A40: glass | B40: 1.1 | C40: =B40/2*0.000001 -> 5.5e-07 | D40: 20 | E40: =D40 -> 20 | F40: =Zeta_Hamaker!$B$15 -> 7.17e-21 | G40: =Zeta_Hamaker!$B$9 -> -0.05 | H40: =Zeta_Hamaker!$C$9 -> -0.051 | I40: =SQRT(2*Constants!$C$10*Constants!$C$5^2*E40/(Constants!$C$8*Constants!$C$9*Constants!$C$17)) -> 4.642686e+08 | J40: =1/I40*1000000000 -> 2.1539256 | K40: =TANH(Constants!$C$11*Constants!$C$5*G40/(4*Constants!$C$17)) -> -0.45782444 | L40: =TANH(Constants!$C$11*Constants!$C$5*H40/(4*Constants!$C$17)) -> -0.46560685 | M40: 18.503064 | N40: =(-(F40*C40/(6*M40/1000000000))/(1+14*(M40/1000000000)/Constants!$C$12))/Constants!$C$17 -> -2.4433346 | O40: =64*PI()*Constants!$C$8*Constants!$C$9*C40*(Constants!$C$17/(Constants!$C$11*Constants!$C$5))^2*K40*L40*EXP(-I40*(M40/1000000000))/Constants!$C$17 -> 0.48968103 | P40: =MAX(-(N40+O40),0) -> 1.9536536 | Q40: yes
A41: glass | B41: 1.1 | C41: =B41/2*0.000001 -> 5.5e-07 | D41: 50 | E41: =D41 -> 50 | F41: =Zeta_Hamaker!$B$15 -> 7.17e-21 | G41: =Zeta_Hamaker!$B$10 -> -0.04 | H41: =Zeta_Hamaker!$C$10 -> -0.038 | I41: =SQRT(2*Constants!$C$10*Constants!$C$5^2*E41/(Constants!$C$8*Constants!$C$9*Constants!$C$17)) -> 7.3407311e+08 | J41: =1/I41*1000000000 -> 1.3622621 | K41: =TANH(Constants!$C$11*Constants!$C$5*G41/(4*Constants!$C$17)) -> -0.37621587 | L41: =TANH(Constants!$C$11*Constants!$C$5*H41/(4*Constants!$C$17)) -> -0.35910851 | M41: 9.3850769 | N41: =(-(F41*C41/(6*M41/1000000000))/(1+14*(M41/1000000000)/Constants!$C$12))/Constants!$C$17 -> -7.4746095 | O41: =64*PI()*Constants!$C$8*Constants!$C$9*C41*(Constants!$C$17/(Constants!$C$11*Constants!$C$5))^2*K41*L41*EXP(-I41*(M41/1000000000))/Constants!$C$17 -> 1.7006633 | P41: =MAX(-(N41+O41),0) -> 5.7739461 | Q41: yes
...

Sheet Kramers
A1: Kramers escape from the secondary minimum -- the single-colloid prediction
A2: D(a) = kT / (6 pi mu a) [Stokes-Einstein] k_r,abs = D * kappa^2 * exp(-|U_sec|/kT)
A3: Well width taken as the Debye length, so the attempt frequency is D*kappa^2. 'anchored' rescales the curve to the glass shared constant at 1.1 um so its SIZE SLOPE is comparable with the fitted k_r -- the absolute rate is ~1e8x too high, which is the second refutation. See dlvo_kramers_size.py and kr_trend_analysis.md.
A5: medium | B5: diameter (um) | C5: IS (mM) | D5: |U_sec| (kT) | E5: D (m2/s) | F5: kappa^2 (1/m2) | G5: attempt freq D*kappa^2 (1/s) | H5: exp(-|U_sec|) | I5: k_r absolute (1/s) | J5: k_r anchored (1/s) | K5: in Li/Tong set?
A6: glass | B6: 0.1 | C6: 1 | K6: -
A7: glass | B7: 0.1 | C7: 3 | K7: -
A8: glass | B8: 0.1 | C8: 6 | D8: =Usec_grid!P8 -> 0.042394536 | E8: =Constants!$C$17/(6*PI()*Constants!$C$13*Usec_grid!C8) -> 4.29622e-12 | F8: =Usec_grid!I8^2 -> 6.4663599e+16 | G8: =E8*F8 -> 277809.05 | H8: =EXP(-D8) -> 0.95849155 | I8: =G8*H8 -> 266277.63 | J8: =Constants!$C$19*I8/$I$40 -> 0.0012450804 | K8: -
A9: glass | B9: 0.1 | C9: 10 | K9: -
A10: glass | B10: 0.1 | C10: 20 | D10: =Usec_grid!P10 -> 0.17760487 | E10: =Constants!$C$17/(6*PI()*Constants!$C$13*Usec_grid!C10) -> 4.29622e-12 | F10: =Usec_grid!I10^2 -> 2.1554533e+17 | G10: =E10*F10 -> 926030.17 | H10: =EXP(-D10) -> 0.83727319 | I10: =G10*H10 -> 775340.23 | J10: =Constants!$C$19*I10/$I$40 -> 0.0036253926 | K10: yes
A11: glass | B11: 0.1 | C11: 50 | D11: =Usec_grid!P11 -> 0.52490419 | E11: =Constants!$C$17/(6*PI()*Constants!$C$13*Usec_grid!C11) -> 4.29622e-12 | F11: =Usec_grid!I11^2 -> 5.3886332e+17 | G11: =E11*F11 -> 2315075.4 | H11: =EXP(-D11) -> 0.59161204 | I11: =G11*H11 -> 1369626.5 | J11: =Constants!$C$19*I11/$I$40 -> 0.0064041997 | K11: yes
A12: glass | B12: 0.2 | C12: 1 | K12: -
A13: glass | B13: 0.2 | C13: 3 | K13: -
A14: glass | B14: 0.2 | C14: 6 | D14: =Usec_grid!P14 -> 0.084789072 | E14: =Constants!$C$17/(6*PI()*Constants!$C$13*Usec_grid!C14) -> 2.14811e-12 | F14: =Usec_grid!I14^2 -> 6.4663599e+16 | G14: =E14*F14 -> 138904.52 | H14: =EXP(-D14) -> 0.91870605 | I14: =G14*H14 -> 127612.43 | J14: =Constants!$C$19*I14/$I$40 -> 0.00059669952 | K14: -
A15: glass | B15: 0.2 | C15: 10 | K15: -
A16: glass | B16: 0.2 | C16: 20 | D16: =Usec_grid!P16 -> 0.35520974 | E16: =Constants!$C$17/(6*PI()*Constants!$C$13*Usec_grid!C16) -> 2.14811e-12 | F16: =Usec_grid!I16^2 -> 2.1554533e+17 | G16: =E16*F16 -> 463015.08 | H16: =EXP(-D16) -> 0.70102639 | I16: =G16*H16 -> 324585.79 | J16: =Constants!$C$19*I16/$I$40 -> 0.001517722 | K16: yes
A17: glass | B17: 0.2 | C17: 50 | D17: =Usec_grid!P17 -> 1.0498084 | E17: =Constants!$C$17/(6*PI()*Constants!$C$13*Usec_grid!C17) -> 2.14811e-12 | F17: =Usec_grid!I17^2 -> 5.3886332e+17 | G17: =E17*F17 -> 1157537.7 | H17: =EXP(-D17) -> 0.35000481 | I17: =G17*H17 -> 405143.76 | J17: =Constants!$C$19*I17/$I$40 -> 0.0018944008 | K17: yes
A18: glass | B18: 0.5 | C18: 1 | K18: -
A19: glass | B19: 0.5 | C19: 3 | K19: -
A20: glass | B20: 0.5 | C20: 6 | D20: =Usec_grid!P20 -> 0.21197268 | E20: =Constants!$C$17/(6*PI()*Constants!$C$13*Usec_grid!C20) -> 8.5924401e-13 | F20: =Usec_grid!I20^2 -> 6.4663599e+16 | G20: =E20*F20 -> 55561.81 | H20: =EXP(-D20) -> 0.8089868 | I20: =G20*H20 -> 44948.771 | J20: =Constants!$C$19*I20/$I$40 -> 0.00021017475 | K20: -
A21: glass | B21: 0.5 | C21: 10 | K21: -
A22: glass | B22: 0.5 | C22: 20 | D22: =Usec_grid!P22 -> 0.88802435 | E22: =Constants!$C$17/(6*PI()*Constants!$C$13*Usec_grid!C22) -> 8.5924401e-13 | F22: =Usec_grid!I22^2 -> 2.1554533e+17 | G22: =E22*F22 -> 185206.03 | H22: =EXP(-D22) -> 0.41146786 | I22: =G22*H22 -> 76206.331 | J22: =Constants!$C$19*I22/$I$40 -> 0.00035633114 | K22: yes
A23: glass | B23: 0.5 | C23: 50 | D23: =Usec_grid!P23 -> 2.624521 | E23: =Constants!$C$17/(6*PI()*Constants!$C$13*Usec_grid!C23) -> 8.5924401e-13 | F23: =Usec_grid!I23^2 -> 5.3886332e+17 | G23: =E23*F23 -> 463015.08 | H23: =EXP(-D23) -> 0.072474466 | I23: =G23*H23 -> 33556.771 | J23: =Constants!$C$19*I23/$I$40 -> 0.0001569072 | K23: yes
A24: glass | B24: 0.98 | C24: 1 | K24: -
A25: glass | B25: 0.98 | C25: 3 | K25: -
A26: glass | B26: 0.98 | C26: 6 | D26: =Usec_grid!P26 -> 0.41546645 | E26: =Constants!$C$17/(6*PI()*Constants!$C$13*Usec_grid!C26) -> 4.383898e-13 | F26: =Usec_grid!I26^2 -> 6.4663599e+16 | G26: =E26*F26 -> 28347.862 | H26: =EXP(-D26) -> 0.66003234 | I26: =G26*H26 -> 18710.506 | J26: =Constants!$C$19*I26/$I$40 -> 8.7487951e-05 | K26: -
A27: glass | B27: 0.98 | C27: 10 | K27: yes
A28: glass | B28: 0.98 | C28: 20 | D28: =Usec_grid!P28 -> 1.7405277 | E28: =Constants!$C$17/(6*PI()*Constants!$C$13*Usec_grid!C28) -> 4.383898e-13 | F28: =Usec_grid!I28^2 -> 2.1554533e+17 | G28: =E28*F28 -> 94492.874 | H28: =EXP(-D28) -> 0.1754278 | I28: =G28*H28 -> 16576.677 | J28: =Constants!$C$19*I28/$I$40 -> 7.7510437e-05 | K28: -
A29: glass | B29: 0.98 | C29: 50 | D29: =Usec_grid!P29 -> 5.1440611 | E29: =Constants!$C$17/(6*PI()*Constants!$C$13*Usec_grid!C29) -> 4.383898e-13 | F29: =Usec_grid!I29^2 -> 5.3886332e+17 | G29: =E29*F29 -> 236232.19 | H29: =EXP(-D29) -> 0.0058339493 | I29: =G29*H29 -> 1378.1666 | J29: =Constants!$C$19*I29/$I$40 -> 6.4441321e-06 | K29: -
A30: glass | B30: 1 | C30: 1 | K30: -
A31: glass | B31: 1 | C31: 3 | K31: -
A32: glass | B32: 1 | C32: 6 | D32: =Usec_grid!P32 -> 0.42394536 | E32: =Constants!$C$17/(6*PI()*Constants!$C$13*Usec_grid!C32) -> 4.29622e-13 | F32: =Usec_grid!I32^2 -> 6.4663599e+16 | G32: =E32*F32 -> 27780.905 | H32: =EXP(-D32) -> 0.65445964 | I32: =G32*H32 -> 18181.481 | J32: =Constants!$C$19*I32/$I$40 -> 8.5014299e-05 | K32: -
A33: glass | B33: 1 | C33: 10 | K33: -
A34: glass | B34: 1 | C34: 20 | D34: =Usec_grid!P34 -> 1.7760487 | E34: =Constants!$C$17/(6*PI()*Constants!$C$13*Usec_grid!C34) -> 4.29622e-13 | F34: =Usec_grid!I34^2 -> 2.1554533e+17 | G34: =E34*F34 -> 92603.017 | H34: =EXP(-D34) -> 0.1693058 | I34: =G34*H34 -> 15678.228 | J34: =Constants!$C$19*I34/$I$40 -> 7.3309406e-05 | K34: yes
A35: glass | B35: 1 | C35: 50 | D35: =Usec_grid!P35 -> 5.2490419 | E35: =Constants!$C$17/(6*PI()*Constants!$C$13*Usec_grid!C35) -> 4.29622e-13 | F35: =Usec_grid!I35^2 -> 5.3886332e+17 | G35: =E35*F35 -> 231507.54 | H35: =EXP(-D35) -> 0.0052525483 | I35: =G35*H35 -> 1216.0045 | J35: =Constants!$C$19*I35/$I$40 -> 5.6858829e-06 | K35: yes
A36: glass | B36: 1.1 | C36: 1 | K36: -
A37: glass | B37: 1.1 | C37: 3 | K37: -
A38: glass | B38: 1.1 | C38: 6 | D38: =Usec_grid!P38 -> 0.46633989 | E38: =Constants!$C$17/(6*PI()*Constants!$C$13*Usec_grid!C38) -> 3.9056546e-13 | F38: =Usec_grid!I38^2 -> 6.4663599e+16 | G38: =E38*F38 -> 25255.368 | H38: =EXP(-D38) -> 0.62729403 | I38: =G38*H38 -> 15842.542 | J38: =Constants!$C$19*I38/$I$40 -> 7.4077716e-05 | K38: yes
A39: glass | B39: 1.1 | C39: 10 | K39: -
A40: glass | B40: 1.1 | C40: 20 | D40: =Usec_grid!P40 -> 1.9536536 | E40: =Constants!$C$17/(6*PI()*Constants!$C$13*Usec_grid!C40) -> 3.9056546e-13 | F40: =Usec_grid!I40^2 -> 2.1554533e+17 | G40: =E40*F40 -> 84184.56 | H40: =EXP(-D40) -> 0.14175521 | I40: =G40*H40 -> 11933.6 | J40: =Constants!$C$19*I40/$I$40 -> 5.58e-05 | K40: yes
A41: glass | B41: 1.1 | C41: 50 | D41: =Usec_grid!P41 -> 5.7739461 | E41: =Constants!$C$17/(6*PI()*Constants!$C$13*Usec_grid!C41) -> 3.9056546e-13 | F41: =Usec_grid!I41^2 -> 5.3886332e+17 | G41: =E41*F41 -> 210461.4 | H41: =EXP(-D41) -> 0.0031074708 | I41: =G41*H41 -> 654.00266 | J41: =Constants!$C$19*I41/$I$40 -> 3.0580335e-06 | K41: yes
...

Sheet Equations
A1: Equations, in the exact form implemented
A3: van der Waals | B3: U_vdw(h) = -(A132 * a_p) / (6h) * 1 / (1 + 14h/lambda) [Gregory-retarded, sphere-plate]
A4: electrostatic | B4: U_edl(h) = 64*pi*eps0*eps_r*a_p*(kT/(z*e))^2 * G1*G2 * exp(-kappa*h) [LSA, constant potential]
B5: G_i = tanh( z*e*zeta_i / (4kT) ) for i = colloid, collector
A6: Debye parameter | B6: kappa = sqrt( 2*N_A*e^2*I / (eps0*eps_r*kT) ), I in mol/m3; Debye length = 1/kappa
A7: secondary minimum | B7: |U_sec| = -min over h > 8 nm of [ U_vdw(h) + U_edl(h) ], reported in units of kT
B8: both terms scale linearly with a_p, so |U_sec| is PROPORTIONAL TO COLLOID RADIUS at fixed chemistry
A9: diffusivity | B9: D(a_p) = kT / (6*pi*mu*a_p) [Stokes-Einstein; ~1/a]
A10: Kramers escape | B10: k_r(a_p) = D * kappa^2 * exp( -|U_sec|/kT ) [overdamped; well width ~ Debye length]
A12: Provenance
B13: |U_sec|: fx_vs_usec.usec(), imported by fx_trend.py as the single copy of this physics. This workbook reproduces it exactly (self-check on every build) and additionally reports h_sec.
B14: Kramers: dlvo_kramers_size.py.
B15: zeta, Hamaker: fx_trend.py ZETA_COLLOID / ZETA_COLLECTOR / A_HAM, from Johnson 2018 Table SI-1; provenance in Records/data_inventory.md section 6.
B16: sizes and ionic strengths: every distinct value in Data/LiTong_experimental_data_tidy.csv.
B17: Reproducer for this workbook: Code/dlvo_parameter_table.py.
A19: CAVEATS
B20: TWO ZETA GAPS, BOTH REAL. No colloid or collector zeta exists at 1, 3 or 10 mM, and no QUARTZ collector zeta at 50 mM. Those rows are greyed and carry no |U_sec|. 3 mM is in the manuscript, so that gap needs a measured or explicitly-flagged interpolated zeta -- not a silent fill.
B21: |U_sec| does NOT encode velocity. Size, ionic strength and mineralogy act through it; the sweep side of trap-vs-sweep capture is a separate, hidden variable.
B22: The 50 mM colloid zeta (-0.040 V) is EXTRAPOLATED beyond the 20 mM end of Table SI-1 -- flagged in part2_apriori_alpha_machinery.md section 1.1a and carried here unchanged.
B23: The Kramers anchor 5.58e-5 /s is the SUPERSEDED glass constant (current 3.75e-5 /s). It is retained because the published anchored curve used it; the anchoring affects only the vertical placement of the curve, never its size slope, which is the refutation.
B24: h_sec is a value, not a formula -- it needs a numerical minimisation. Re-run the reproducer after any material change to a zeta or Hamaker constant.
